Workbook

Sheet Task 2
A1: Please change the color of the highest and lowest order amount
A4: Sales Report
A5: Order Date | B5: Sales Agent Name | C5: Car Type | D5: Car price | E5: Count | F5: Total Sales
A6: 43586 | B6: Ahmed | C6: Toyota | D6: 590000 | E6: 1 | F6: =D6*E6 -> 590000
A7: 43587 | B7: Hossam | C7: Jeep | D7: 750000 | E7: 2 | F7: =D7*E7 -> 1500000
A8: 43588 | B8: Abdullah | C8: Toyota | D8: 590000 | E8: 1 | F8: =D8*E8 -> 590000
A9: 43589 | B9: Mona | C9: Volkswagen | D9: 460000 | E9: 1 | F9: =D9*E9 -> 460000
A10: 43590 | B10: Farida | C10: BMW | D10: 790000 | E10: 3 | F10: =D10*E10 -> 2370000
A11: 43591 | B11: Ahmed | C11: Kia | D11: 375000 | E11: 2 | F11: =D11*E11 -> 750000
A12: 43592 | B12: Hossam | C12: Toyota | D12: 590000 | E12: 3 | F12: =D12*E12 -> 1770000
A13: 43593 | B13: Ahmed | C13: Jeep | D13: 750000 | E13: 2 | F13: =D13*E13 -> 1500000
A14: 43594 | B14: Mona | C14: Toyota | D14: 590000 | E14: 3 | F14: =D14*E14 -> 1770000
A15: 43595 | B15: Abdullah | C15: Jeep | D15: 750000 | E15: 2 | F15: =D15*E15 -> 1500000
A16: 43596 | B16: Hossam | C16: Volkswagen | D16: 460000 | E16: 1 | F16: =D16*E16 -> 460000
A17: 43597 | B17: Mona | C17: Volkswagen | D17: 460000 | E17: 1 | F17: =D17*E17 -> 460000
... A35: 43615 | B35: Ali | C35: Volkswagen | D35: 460000 | E35: 1 | F35: =D35*E35 -> 460000

Sheet Task 3
A1: Please highlight the by green all the results that more than J3 Amount and by red any results below this number
A2: Please find the highest and the lowest results
I3: Target | J3: 1000
A4: Sales Report per Thousand | I4: The lowest Sales Amount | J4: =MIN(B6:G14) -> 189.84375
A5: Sales Person | B5: Jan | C5: Feb | D5: Mar | E5: Apr | F5: May | G5: Jun | I5: The highest result | J5: =MAX(B6:G14) -> 6831
A6: Ahmed | B6: 1200 | C6: 840 | D6: 900 | E6: 1201 | F6: 840.7 | G6: 901
A7: Hossam | B7: 600 | C7: 420 | D7: 450 | E7: 600.5 | F7: 420.35 | G7: 450.5
A8: Abdullah | B8: 720 | C8: 210 | D8: 1350 | E8: 720.6 | F8: 210.175 | G8: 1351.5
A9: Mona | B9: 1320 | C9: 1242 | D9: 675 | E9: 1321.1 | F9: 920 | G9: 675.75
A10: Farida | B10: 792 | C10: 1330 | D10: 1012.5 | E10: 792.66 | F10: 1380 | G10: 1013.625
A11: Ali | B11: 1188 | C11: 1995 | D11: 506.25 | E11: 1250 | F11: 2070 | G11: 506.8125
A12: Hand | B12: 1742.4 | C12: 2926 | D12: 253.125 | E12: 1743.852 | F12: 3036 | G12: 253.40625
A13: Tamer | B13: 1045.44 | C13: 4389 | D13: 379.6875 | E13: 1046.3112 | F13: 4554 | G13: 380.10938
A14: Othman | B14: 1568.16 | C14: 6583.5 | D14: 189.84375 | E14: 1569.4668 | F14: 6831 | G14: 190.05469

Sheet Task 4
A1: Please fill the yellow cells by the related equation
A4: Sales Report
A5: Order Date | B5: Sales Agent Name | C5: Car Type | D5: Car price | E5: Count | F5: Total Sales | I5: Item | J5: Amount
A6: 43586 | B6: Ahmed | C6: Toyota | D6: 590000 | E6: 1 | F6: =D6*E6 -> 590000 | I6: Total Sales Amount | J6: =SUM(F6:F35) -> 29365000
A7: 43587 | B7: Hossam | C7: Jeep | D7: 750000 | E7: 2 | F7: =D7*E7 -> 1500000 | I7: Total Sold Cars | J7: =SUM(E6:E35) -> 50
A8: 43588 | B8: Abdullah | C8: Toyota | D8: 590000 | E8: 1 | F8: =D8*E8 -> 590000 | I8: Count of orders | J8: =COUNT(A6:A35) -> 30
A9: 43589 | B9: Mona | C9: Volkswagen | D9: 460000 | E9: 1 | F9: =D9*E9 -> 460000 | I9: Average order Amount | J9: =AVERAGE(F:F) -> 978833.33
A10: 43590 | B10: Farida | C10: BMW | D10: 790000 | E10: 3 | F10: =D10*E10 -> 2370000
A11: 43591 | B11: Ahmed | C11: Kia | D11: 375000 | E11: 2 | F11: =D11*E11 -> 750000
A12: 43592 | B12: Hossam | C12: Toyota | D12: 590000 | E12: 3 | F12: =D12*E12 -> 1770000
A13: 43593 | B13: Ahmed | C13: Jeep | D13: 750000 | E13: 2 | F13: =D13*E13 -> 1500000
A14: 43594 | B14: Mona | C14: Toyota | D14: 590000 | E14: 3 | F14: =D14*E14 -> 1770000
A15: 43595 | B15: Abdullah | C15: Jeep | D15: 750000 | E15: 2 | F15: =D15*E15 -> 1500000
A16: 43596 | B16: Hossam | C16: Volkswagen | D16: 460000 | E16: 1 | F16: =D16*E16 -> 460000
A17: 43597 | B17: Mona | C17: Volkswagen | D17: 460000 | E17: 1 | F17: =D17*E17 -> 460000
A18: 43598 | B18: Farida | C18: Jeep | D18: 750000 | E18: 1 | F18: =D18*E18 -> 750000
A19: 43599 | B19: Farida | C19: Toyota | D19: 590000 | E19: 2 | F19: =D19*E19 -> 1180000
A20: 43600 | B20: Ahmed | C20: Kia | D20: 375000 | E20: 2 | F20: =D20*E20 -> 750000
A21: 43601 | B21: Hossam | C21: BMW | D21: 790000 | E21: 1 | F21: =D21*E21 -> 790000
... A35: 43615 | B35: Ali | C35: Volkswagen | D35: 460000 | E35: 1 | F35: =D35*E35 -> 460000

Sheet Task 6
A1: Please prepare a report for each one of sales persons results | F1: sumifs
A2: Please find the best sales person according to his sales amount | F2: countifs
A4: Sales Report
A5: Order Date | B5: Sales Agent Name | C5: Car Type | D5: Car price | E5: Count | F5: Total Sales | N5: Sumifs | U5: Countifs
A6: 43586 | B6: Ahmed | C6: Toyota | D6: 590000 | E6: 1 | F6: =D6*E6 -> 590000
A7: 43587 | B7: Hossam | C7: Jeep | D7: 750000 | E7: 2 | F7: =D7*E7 -> 1500000 | U7: Toyota | V7: BMW | W7: Kia
A8: 43588 | B8: Abdullah | C8: Toyota | D8: 590000 | E8: 1 | F8: =D8*E8 -> 590000 | N8: Ahmed | O8: Farida | P8: Hossam | T8: Ahmed | U8: =COUNTIFS(B6:B35,B6,C6:C35,C6) -> 2 | V8: =COUNTIFS(B6:B35,B6,C6:C35,C10) -> 1 | W8: =COUNTIFS(B6:B35,B6,C6:C35,C11) -> 2
A9: 43589 | B9: Mona | C9: Volkswagen | D9: 460000 | E9: 1 | F9: =D9*E9 -> 460000 | M9: Toyota | N9: =SUMIFS(F6:F35,B6:B35,N8,C6:C35,M9) -> 2360000 | O9: =SUMIFS(F6:F35,B6:B35,B10,C6:C35,C6) -> 1180000 | P9: =SUMIFS(F6:F35,B6:B35,B12,C6:C35,C6) -> 1770000 | T9: Hossam | U9: =COUNTIFS(B6:B35,B7,C6:C35,C8) -> 1 | V9: =COUNTIFS(B6:B35,B7,C6:C35,C10) -> 1 | W9: =COUNTIFS(B6:B35,B7,C6:C35,C11) -> 2
A10: 43590 | B10: Farida | C10: BMW | D10: 790000 | E10: 3 | F10: =D10*E10 -> 2370000 | M10: Jeep | N10: =SUMIFS(F6:F35,B6:B35,B6,C6:C35,C13) -> 1500000 | O10: =SUMIFS(F6:F35,B6:B35,B10,C6:C35,C7) -> 1500000 | P10: =SUMIFS(F6:F35,B6:B35,B7,C6:C35,C13) -> 2250000 | T10: Mona | U10: =COUNTIFS(B6:B35,B9,C6:C35,C8) -> 2 | V10: =COUNTIFS(B6:B35,B9,C6:C35,C10) -> 0 | W10: =COUNTIFS(B6:B35,B9,C6:C35,C11) -> 0
A11: 43591 | B11: Ahmed | C11: Kia | D11: 375000 | E11: 2 | F11: =D11*E11 -> 750000 | M11: BMW | N11: =SUMIFS(F6:F35,B6:B35,N8,C6:C35,M11) -> 1580000 | O11: =SUMIFS(F6:F35,B6:B35,B10,C6:C35,C10) -> 2370000 | P11: =SUMIFS(F6:F35,B6:B35,B12,C6:C35,C10) -> 790000
A12: 43592 | B12: Hossam | C12: Toyota | D12: 590000 | E12: 3 | F12: =D12*E12 -> 1770000
A13: 43593 | B13: Ahmed | C13: Jeep | D13: 750000 | E13: 2 | F13: =D13*E13 -> 1500000
A14: 43594 | B14: Mona | C14: Toyota | D14: 590000 | E14: 3 | F14: =D14*E14 -> 1770000
A15: 43595 | B15: Abdullah | C15: Jeep | D15: 750000 | E15: 2 | F15: =D15*E15 -> 1500000
A16: 43596 | B16: Hossam | C16: Volkswagen | D16: 460000 | E16: 1 | F16: =D16*E16 -> 460000
A17: 43597 | B17: Mona | C17: Volkswagen | D17: 460000 | E17: 1 | F17: =D17*E17 -> 460000
A18: 43598 | B18: Farida | C18: Jeep | D18: 750000 | E18: 1 | F18: =D18*E18 -> 750000
A19: 43599 | B19: Farida | C19: Toyota | D19: 590000 | E19: 2 | F19: =D19*E19 -> 1180000
A20: 43600 | B20: Ahmed | C20: Kia | D20: 375000 | E20: 2 | F20: =D20*E20 -> 750000
A21: 43601 | B21: Hossam | C21: BMW | D21: 790000 | E21: 1 | F21: =D21*E21 -> 790000
A22: 43602 | B22: Abdullah | C22: BMW | D22: 790000 | E22: 1 | F22: =D22*E22 -> 790000
A23: 43603 | B23: Ali | C23: Toyota | D23: 590000 | E23: 2 | F23: =D23*E23 -> 1180000
... A35: 43615 | B35: Ali | C35: Volkswagen | D35: 460000 | E35: 1 | F35: =D35*E35 -> 460000
A56: t

Sheet Task 7
A1: Please list the car prices for each order and calculate the full order amount
J3: Car Type | K3: Price
A4: Order Date | B4: Sales Agent Name | C4: Car Type | D4: Car price | E4: Count | F4: Total Sales | J4: Toyota | K4: 590000
A5: 43586 | B5: Ahmed | C5: Toyota | D5: =_xlfn.XLOOKUP(C5,J:J,K:K) -> 590000 | E5: 1 | F5: =D5*E5 -> 590000 | J5: Jeep | K5: 750000
A6: 43587 | B6: Hossam | C6: Jeep | D6: =_xlfn.XLOOKUP(C6,J:J,K:K) -> 750000 | E6: 2 | F6: =D6*E6 -> 1500000 | J6: Volkswagen | K6: 460000
A7: 43588 | B7: Abdullah | C7: Toyota | D7: =_xlfn.XLOOKUP(C7,J:J,K:K) -> 590000 | E7: 1 | F7: =D7*E7 -> 590000 | J7: BMW | K7: 790000
A8: 43589 | B8: Mona | C8: Volkswagen | D8: =_xlfn.XLOOKUP(C8,J:J,K:K) -> 460000 | E8: 1 | F8: =D8*E8 -> 460000 | J8: Kia | K8: 375000
A9: 43590 | B9: Farida | C9: BMW | D9: =_xlfn.XLOOKUP(C9,J:J,K:K) -> 790000 | E9: 3 | F9: =D9*E9 -> 2370000 | J9: Mazda | K9: 348000
A10: 43591 | B10: Ahmed | C10: Kia | D10: =_xlfn.XLOOKUP(C10,J:J,K:K) -> 375000 | E10: 2 | F10: =D10*E10 -> 750000
A11: 43592 | B11: Hossam | C11: Toyota | D11: =_xlfn.XLOOKUP(C11,J:J,K:K) -> 590000 | E11: 3 | F11: =D11*E11 -> 1770000
A12: 43593 | B12: Ahmed | C12: Jeep | D12: =_xlfn.XLOOKUP(C12,J:J,K:K) -> 750000 | E12: 2 | F12: =D12*E12 -> 1500000
A13: 43594 | B13: Mona | C13: Toyota | D13: =_xlfn.XLOOKUP(C13,J:J,K:K) -> 590000 | E13: 3 | F13: =D13*E13 -> 1770000
A14: 43595 | B14: Abdullah | C14: Jeep | D14: =_xlfn.XLOOKUP(C14,J:J,K:K) -> 750000 | E14: 2 | F14: =D14*E14 -> 1500000
A15: 43596 | B15: Hossam | C15: Volkswagen | D15: =_xlfn.XLOOKUP(C15,J:J,K:K) -> 460000 | E15: 1 | F15: =D15*E15 -> 460000
A16: 43597 | B16: Mona | C16: Volkswagen | D16: =_xlfn.XLOOKUP(C16,J:J,K:K) -> 460000 | E16: 1 | F16: =D16*E16 -> 460000
A17: 43598 | B17: Farida | C17: Jeep | D17: =_xlfn.XLOOKUP(C17,J:J,K:K) -> 750000 | E17: 1 | F17: =D17*E17 -> 750000
A18: 43599 | B18: Farida | C18: Toyota | D18: =_xlfn.XLOOKUP(C18,J:J,K:K) -> 590000 | E18: 2 | F18: =D18*E18 -> 1180000
A19: 43600 | B19: Ahmed | C19: Kia | D19: =_xlfn.XLOOKUP(C19,J:J,K:K) -> 375000 | E19: 2 | F19: =D19*E19 -> 750000
A20: 43601 | B20: Hossam | C20: BMW | D20: =_xlfn.XLOOKUP(C20,J:J,K:K) -> 790000 | E20: 1 | F20: =D20*E20 -> 790000
A21: 43602 | B21: Abdullah | C21: BMW | D21: =_xlfn.XLOOKUP(C21,J:J,K:K) -> 790000 | E21: 1 | F21: =D21*E21 -> 790000
... A34: 43615 | B34: Ali | C34: Volkswagen | D34: =_xlfn.XLOOKUP(C34,J:J,K:K) -> 460000 | E34: 1 | F34: =D34*E34 -> 460000

Sheet Task 8
A1: Please prepare a new bill for your order
H3: Car Type | I3: Price
A4: Car Type | B4: Car price | C4: Count | D4: Total Sales | H4: Toyota | I4: 590000
A5: Toyota | B5: =_xlfn.XLOOKUP(A5,H:H,I:I) -> 590000 | C5: =SUMIFS('Task 7'!E5:E34,'Task 7'!C5:C34,'Task 8'!A5) -> 17 | D5: =B5*C5 -> 10030000 | H5: Jeep | I5: 750000
A6: Jeep | B6: =_xlfn.XLOOKUP(A6,H:H,I:I) -> 750000 | C6: =SUMIFS('Task 7'!E6:E35,'Task 7'!C6:C35,'Task 8'!A6) -> 9 | D6: =B6*C6 -> 6750000 | H6: Volkswagen | I6: 460000
A7: Volkswagen | B7: =_xlfn.XLOOKUP(A7,H:H,I:I) -> 460000 | C7: =SUMIFS('Task 7'!E7:E36,'Task 7'!C7:C36,'Task 8'!A7) -> 8 | D7: =B7*C7 -> 3680000 | H7: BMW | I7: 790000
A8: BMW | B8: =_xlfn.XLOOKUP(A8,H:H,I:I) -> 790000 | C8: =SUMIFS('Task 7'!E8:E37,'Task 7'!C8:C37,'Task 8'!A8) -> 7 | D8: =B8*C8 -> 5530000 | H8: Kia | I8: 375000
A9: Kia | B9: =_xlfn.XLOOKUP(A9,H:H,I:I) -> 375000 | C9: =SUMIFS('Task 7'!E9:E38,'Task 7'!C9:C38,'Task 8'!A9) -> 9 | D9: =B9*C9 -> 3375000 | H9: Mazda | I9: 348000
A10: Mazda | B10: =_xlfn.XLOOKUP(A10,H:H,I:I) -> 348000 | C10: =SUMIFS('Task 7'!E10:E39,'Task 7'!C10:C39,'Task 8'!A10) -> 0 | D10: =B10*C10 -> 0
A16: Total | C16: =SUM(C5:C9) -> 50 | D16: =SUM(D5:D9) -> 29365000 | J16: لا يوجد COUNT لل Mazda هسيبها فاضية اضغط على الخلية انا موضح بالتالي هسيبها الباقي كان ليه count جمعناه ب countifs من الداتا اللى ف الصفحه اللى قبلها

Sheet pivot table
A3: Row Labels | B3: Sum of Follow Up | C3: Sum of Call | D3: Sum of Email | E3: Sum of SMS | F3: Sum of Won Deals | G3: Sum of Lost Deals
A4: Jan | B4: 2770.75 | C4: 16624.5 | D4: 3324.9 | E4: 1662.45 | F4: 2216.6 | G4: 6095.65
A5: Feb | B5: 2706.5 | C5: 16239 | D5: 3247.8 | E5: 1623.9 | F5: 2165.2 | G5: 5954.3
A6: Mar | B6: 1961 | C6: 11766 | D6: 2353.2 | E6: 1176.6 | F6: 1568.8 | G6: 4314.2
A7: Dec | B7: 103 | C7: 618 | D7: 123.6 | E7: 61.8 | F7: 82.4 | G7: 226.6
A8: Grand Total | B8: 7541.25 | C8: 45247.5 | D8: 9049.5 | E8: 4524.75 | F8: 6033 | G8: 16590.75

Sheet 9
A1: Activity Date | B1: Agent Code | C1: Agent Name | D1: Total leads | E1: Won Deals | F1: Lost Deals | G1: Follow Up | H1: Call | I1: Email | J1: SMS | K1: Answered - Call Status | L1: No answer - Call Status | M1: Closed mobile - Call Status | N1: Canceled - Call Status | O1: Wrong number - Call Status | Q1: Use data table to Build Weekly & Monthly Tables that to present the below points by Employee
A2: 43465 | B2: 4 | C2: Aya | D2: 30 | E2: 6 | F2: 16.5 | G2: 7.5 | H2: 45 | I2: 9 | J2: 4.5 | K2: 24.75 | L2: 4.5 | M2: 6.75 | N2: 3.15 | O2: 5.85 | Q2: Breakdown of activity
A3: 43465 | B3: 16 | C3: Essam | D3: 40 | E3: 8 | F3: 22 | G3: 10 | H3: 60 | I3: 12 | J3: 6 | K3: 33 | L3: 6 | M3: 9 | N3: 4.2 | O3: 7.8 | Q3: Breakdown of deals status
A4: 43465 | B4: 3 | C4: Emad | D4: 30 | E4: 6 | F4: 16.5 | G4: 7.5 | H4: 45 | I4: 9 | J4: 4.5 | K4: 24.75 | L4: 4.5 | M4: 6.75 | N4: 3.15 | O4: 5.85 | Q4: Are their any activity happened on the weekend ? If yes please show it
A5: 43465 | B5: 2 | C5: Mohamed | D5: 20 | E5: 4 | F5: 11 | G5: 5 | H5: 30 | I5: 6 | J5: 3 | K5: 16.5 | L5: 3 | M5: 4.5 | N5: 2.1 | O5: 3.9 | Q5: Using Pivot Table
A6: 43465 | B6: 1 | C6: Ahmed | D6: 15 | E6: 3 | F6: 8.25 | G6: 3.75 | H6: 22.5 | I6: 4.5 | J6: 2.25 | K6: 12.375 | L6: 2.25 | M6: 3.375 | N6: 1.575 | O6: 2.925
A7: 43465 | B7: 18 | C7: Shenawy | D7: 50 | E7: 10 | F7: 27.5 | G7: 12.5 | H7: 75 | I7: 15 | J7: 7.5 | K7: 41.25 | L7: 7.5 | M7: 11.25 | N7: 5.25 | O7: 9.75
A8: 43465 | B8: 9 | C8: Waled | D8: 60 | E8: 12 | F8: 33 | G8: 15 | H8: 90 | I8: 18 | J8: 9 | K8: 49.5 | L8: 9 | M8: 13.5 | N8: 6.3 | O8: 11.7
A9: 43465 | B9: 6 | C9: Ragy | D9: 45 | E9: 9 | F9: 24.75 | G9: 11.25 | H9: 67.5 | I9: 13.5 | J9: 6.75 | K9: 37.125 | L9: 6.75 | M9: 10.125 | N9: 4.725 | O9: 8.775
A10: 43465 | B10: 15 | C10: Eman | D10: 65 | E10: 13 | F10: 35.75 | G10: 16.25 | H10: 97.5 | I10: 19.5 | J10: 9.75 | K10: 53.625 | L10: 9.75 | M10: 14.625 | N10: 6.825 | O10: 12.675
A11: 43465 | B11: 8 | C11: Hossam | D11: 57 | E11: 11.4 | F11: 31.35 | G11: 14.25 | H11: 85.5 | I11: 17.1 | J11: 8.55 | K11: 47.025 | L11: 8.55 | M11: 12.825 | N11: 5.985 | O11: 11.115
A12: 43467 | B12: 7 | C12: Hend | D12: 54 | E12: 10.8 | F12: 29.7 | G12: 13.5 | H12: 81 | I12: 16.2 | J12: 8.1 | K12: 44.55 | L12: 8.1 | M12: 12.15 | N12: 5.67 | O12: 10.53
A13: 43467 | B13: 10 | C13: Abdullah | D13: 32 | E13: 6.4 | F13: 17.6 | G13: 8 | H13: 48 | I13: 9.6 | J13: 4.8 | K13: 26.4 | L13: 4.8 | M13: 7.2 | N13: 3.36 | O13: 6.24
A14: 43467 | B14: 21 | C14: Abd El Rahman | D14: 12 | E14: 2.4 | F14: 6.6 | G14: 3 | H14: 18 | I14: 3.6 | J14: 1.8 | K14: 9.9 | L14: 1.8 | M14: 2.7 | N14: 1.26 | O14: 2.34
A15: 43467 | B15: 14 | C15: Sara | D15: 78 | E15: 15.6 | F15: 42.9 | G15: 19.5 | H15: 117 | I15: 23.4 | J15: 11.7 | K15: 64.35 | L15: 11.7 | M15: 17.55 | N15: 8.19 | O15: 15.21
A16: 43467 | B16: 5 | C16: Mona | D16: 80 | E16: 16 | F16: 44 | G16: 20 | H16: 120 | I16: 24 | J16: 12 | K16: 66 | L16: 12 | M16: 18 | N16: 8.4 | O16: 15.6
A17: 43467 | B17: 12 | C17: Nada | D17: 55 | E17: 11 | F17: 30.25 | G17: 13.75 | H17: 82.5 | I17: 16.5 | J17: 8.25 | K17: 45.375 | L17: 8.25 | M17: 12.375 | N17: 5.775 | O17: 10.725
... A561: 43551 | B561: 13 | C561: Gomaa | D561: 52 | E561: 10.4 | F561: 28.6 | G561: 13 | H561: 78 | I561: 15.6 | J561: 7.8 | K561: 42.9 | L561: 7.8 | M561: 11.7 | N561: 5.46 | O561: 10.14

Sheet 10
A2: MATCH - INDEX
A5: Agent Code | B5: Agent Name | C5: 1 | D5: 2 | E5: 3 | F5: 4 | I5: Agent Name | J5: Month | K5: Result
A6: 4 | B6: Aya | C6: 15 | D6: 24 | E6: 24 | F6: 54 | I6: Ahmed | J6: 1 | K6: =INDEX(C6:F12,MATCH(I6,B6:B12,0),MATCH(J6,C5:F5,0)) -> 40
A7: 16 | B7: Essam | C7: 18 | D7: 45 | E7: 76 | F7: 36
A8: 3 | B8: Emad | C8: 30 | D8: 23 | E8: 35 | F8: 65
A9: 2 | B9: Mohamed | C9: 35 | D9: 40 | E9: 36 | F9: 38 | I9: Agent Name | J9: Month
A10: 1 | B10: Ahmed | C10: 40 | D10: 57 | E10: 37 | F10: 48.333333 | I10: Waled | J10: 1 | K10: =INDEX(C6:F12,MATCH(I10,B6:B12,0),MATCH(J10,C5:F5,0)) -> 50
A11: 18 | B11: Shenawy | C11: 45 | D11: 74 | E11: 38 | F11: 49.333333
A12: 9 | B12: Waled | C12: 50 | D12: 91 | E12: 39 | F12: 50.333333
I14: Agent Name | J14: Month
I15: Ahmed | J15: 1 | K15: =INDEX(C6:F12,MATCH(I15,B6:B12,0),MATCH(J15,C5:F5,0)) -> 40

Sheet 12
I2: فلترة فواتير بالاسم
I6: FILTER
B7: 43586 | C7: Ahmed | D7: Toyota | E7: 3220227 | I7: Hossam
B8: 43587 | C8: Hossam | D8: Jeep | E8: 2636248 | W8: {=_xlfn.UNIQUE(C7:C36)} -> Ahmed
B9: 43588 | C9: Abdullah | D9: Toyota | E9: 1189039 | W9: Hossam
B10: 43589 | C10: Mona | D10: Volkswagen | E10: 2498993 | I10: Result | W10: Abdullah
B11: 43590 | C11: Farida | D11: BMW | E11: 1602201 | I11: {=_xlfn._xlws.FILTER(C:E,C:C=I7,"not found")} -> Hossam | J11: Jeep | K11: 2636248 | W11: Mona
B12: 43591 | C12: Ahmed | D12: Kia | E12: 3452594 | I12: Hossam | J12: Toyota | K12: 1237464 | W12: Farida
B13: 43592 | C13: Hossam | D13: Toyota | E13: 1237464 | I13: Hossam | J13: Volkswagen | K13: 2813226 | W13: Ali
B14: 43593 | C14: Ahmed | D14: Jeep | E14: 4388211 | I14: Hossam | J14: BMW | K14: 4936405
B15: 43594 | C15: Mona | D15: Toyota | E15: 2305153 | I15: Hossam | J15: Kia | K15: 2840242
B16: 43595 | C16: Abdullah | D16: Jeep | E16: 2107092 | I16: Hossam | J16: Kia | K16: 1877946
B17: 43596 | C17: Hossam | D17: Volkswagen | E17: 2813226 | I17: Hossam | J17: Jeep | K17: 3128119
B18: 43597 | C18: Mona | D18: Volkswagen | E18: 4765963
B19: 43598 | C19: Farida | D19: Jeep | E19: 4850348
B20: 43599 | C20: Farida | D20: Toyota | E20: 1003502
B21: 43600 | C21: Ahmed | D21: Kia | E21: 4819337
B22: 43601 | C22: Hossam | D22: BMW | E22: 4936405
B23: 43602 | C23: Abdullah | D23: BMW | E23: 4607292
B24: 43603 | C24: Ali | D24: Toyota | E24: 3061662 | I24: دي الفواتير اللى اعلى من 2 مليون جنيه
B25: 43604 | C25: Hossam | D25: Kia | E25: 2840242
B26: 43605 | C26: Ali | D26: Toyota | E26: 1527272 | I26: {=_xlfn._xlws.FILTER(C:E,E:E>2000000,"Not fond")} -> Ahmed | J26: Toyota | K26: 3220227
B27: 43606 | C27: Farida | D27: Jeep | E27: 4383809 | I27: Hossam | J27: Jeep | K27: 2636248
B28: 43607 | C28: Abdullah | D28: Volkswagen | E28: 4776249 | I28: Mona | J28: Volkswagen | K28: 2498993
B29: 43608 | C29: Abdullah | D29: Volkswagen | E29: 4023284 | I29: Ahmed | J29: Kia | K29: 3452594
B30: 43609 | C30: Farida | D30: Kia | E30: 2225535 | I30: Ahmed | J30: Jeep | K30: 4388211
B31: 43610 | C31: Ahmed | D31: BMW | E31: 4401079 | I31: Mona | J31: Toyota | K31: 2305153
B32: 43611 | C32: Mona | D32: Toyota | E32: 4530609 | I32: Abdullah | J32: Jeep | K32: 2107092
B33: 43612 | C33: Hossam | D33: Kia | E33: 1877946 | I33: Hossam | J33: Volkswagen | K33: 2813226
B34: 43613 | C34: Ahmed | D34: Toyota | E34: 3769009 | I34: Mona | J34: Volkswagen | K34: 4765963
B35: 43614 | C35: Hossam | D35: Jeep | E35: 3128119 | I35: Farida | J35: Jeep | K35: 4850348
B36: 43615 | C36: Ali | D36: Volkswagen | E36: 1175964 | I36: Ahmed | J36: Kia | K36: 4819337
I37: Hossam | J37: BMW | K37: 4936405
I38: Abdullah | J38: BMW | K38: 4607292
I39: Ali | J39: Toyota | K39: 3061662
I40: Hossam | J40: Kia | K40: 2840242
I41: Farida | J41: Jeep | K41: 4383809
I42: Abdullah | J42: Volkswagen | K42: 4776249
I43: Abdullah | J43: Volkswagen | K43: 4023284
I44: Farida | J44: Kia | K44: 2225535
...

Sheet 13
H2: Count How many times this Product appeard
D3: Sub-Category | E3: Product Name | F3: Sales Price
D4: Bookcases | E4: Bush Somerset Collection Bookcase | F4: 261.96 | H4: products | I4: Number of #
D5: Chairs | E5: Hon Deluxe Fabric Upholstered Stacking Chairs, Rounded Back | F5: 731.94 | H5: Xerox | I5: =COUNTIFS(E:E,H5) -> 0
D6: Labels | E6: Self-Adhesive Address Labels for Typewriters by Universal | F6: 14.62 | H6: Mitel 5320 IP Phone VoIP phone | I6: =COUNTIFS(E:E,H6) -> 1
D7: Tables | E7: Bretford CR4500 Series Slim Rectangular Table | F7: 957.5775
D8: Storage | E8: Eldon Fold 'N Roll Cart System | F8: 22.368
D9: Furnishings | E9: Eldon Expressions Wood and Plastic Desk Accessories, Cherry Wood | F9: 48.86
D10: Art | E10: Newell 322 | F10: 7.28
D11: Phones | E11: Mitel 5320 IP Phone VoIP phone | F11: 907.152
D12: Binders | E12: DXL Angle-View Binders with Locking Rings by Samsill | F12: 18.504
D13: Appliances | E13: Belkin F5C206VTEL 6 Outlet Surge | F13: 114.9
D14: Tables | E14: Chromcraft Rectangular Conference Tables | F14: 1706.184
D15: Phones | E15: Konftel 250 Conference phone - Charcoal black | F15: 911.424
D16: Paper | E16: Xerox 1967 | F16: 15.552
D17: Binders | E17: Fellowes PB200 Plastic Comb Binding Machine | F17: 407.976
D18: Appliances | E18: Holmes Replacement Filter for HEPA Air Cleaner, Very Large Room, HEPA Filter | F18: 68.81
... D1010: Phones | E1010: OtterBox Commuter Series Case - Samsung Galaxy S4 | F1010: 124.95

Sheet Hend
A1: Hend
E4: total leads
E5: =SUM(E20:E44) -> 1175
E9: won deals
E10: =SUM(F20:F44) -> 235
E14: total working days
E15: =COUNTIFS(D20:D49,A1) -> 30
B20: {=_xlfn._xlws.FILTER('9'!A:O,'9'!C:C=Hend!A1,"not found")} -> 43467 | C20: 7 | D20: Hend | E20: 54 | F20: 10.8 | G20: 29.7 | H20: 13.5 | I20: 81 | J20: 16.2 | K20: 8.1 | L20: 44.55 | M20: 8.1 | N20: 12.15 | O20: 5.67 | P20: 10.53
B21: 43469 | C21: 7 | D21: Hend | E21: 48 | F21: 9.6 | G21: 26.4 | H21: 12 | I21: 72 | J21: 14.4 | K21: 7.2 | L21: 39.6 | M21: 7.2 | N21: 10.8 | O21: 5.04 | P21: 9.36
B22: 43472 | C22: 7 | D22: Hend | E22: 60 | F22: 12 | G22: 33 | H22: 15 | I22: 90 | J22: 18 | K22: 9 | L22: 49.5 | M22: 9 | N22: 13.5 | O22: 6.3 | P22: 11.7
B23: 43474 | C23: 7 | D23: Hend | E23: 36 | F23: 7.2 | G23: 19.8 | H23: 9 | I23: 54 | J23: 10.8 | K23: 5.4 | L23: 29.7 | M23: 5.4 | N23: 8.1 | O23: 3.78 | P23: 7.02
B24: 43479 | C24: 7 | D24: Hend | E24: 45 | F24: 9 | G24: 24.75 | H24: 11.25 | I24: 67.5 | J24: 13.5 | K24: 6.75 | L24: 37.125 | M24: 6.75 | N24: 10.125 | O24: 4.725 | P24: 8.775
B25: 43475 | C25: 7 | D25: Hend | E25: 46 | F25: 9.2 | G25: 25.3 | H25: 11.5 | I25: 69 | J25: 13.8 | K25: 6.9 | L25: 37.95 | M25: 6.9 | N25: 10.35 | O25: 4.83 | P25: 8.97
B26: 43486 | C26: 7 | D26: Hend | E26: 70 | F26: 14 | G26: 38.5 | H26: 17.5 | I26: 105 | J26: 21 | K26: 10.5 | L26: 57.75 | M26: 10.5 | N26: 15.75 | O26: 7.35 | P26: 13.65
B27: 43490 | C27: 7 | D27: Hend | E27: 65 | F27: 13 | G27: 35.75 | H27: 16.25 | I27: 97.5 | J27: 19.5 | K27: 9.75 | L27: 53.625 | M27: 9.75 | N27: 14.625 | O27: 6.825 | P27: 12.675
B28: 43487 | C28: 7 | D28: Hend | E28: 15 | F28: 3 | G28: 8.25 | H28: 3.75 | I28: 22.5 | J28: 4.5 | K28: 2.25 | L28: 12.375 | M28: 2.25 | N28: 3.375 | O28: 1.575 | P28: 2.925
B29: 43502 | C29: 7 | D29: Hend | E29: 60 | F29: 12 | G29: 33 | H29: 15 | I29: 90 | J29: 18 | K29: 9 | L29: 49.5 | M29: 9 | N29: 13.5 | O29: 6.3 | P29: 11.7
B30: 43479 | C30: 7 | D30: Hend | E30: 50 | F30: 10 | G30: 27.5 | H30: 12.5 | I30: 75 | J30: 15 | K30: 7.5 | L30: 41.25 | M30: 7.5 | N30: 11.25 | O30: 5.25 | P30: 9.75
B31: 43504 | C31: 7 | D31: Hend | E31: 45 | F31: 9 | G31: 24.75 | H31: 11.25 | I31: 67.5 | J31: 13.5 | K31: 6.75 | L31: 37.125 | M31: 6.75 | N31: 10.125 | O31: 4.725 | P31: 8.775
B32: 43511 | C32: 7 | D32: Hend | E32: 23 | F32: 4.6 | G32: 12.65 | H32: 5.75 | I32: 34.5 | J32: 6.9 | K32: 3.45 | L32: 18.975 | M32: 3.45 | N32: 5.175 | O32: 2.415 | P32: 4.485
... B49: 43544 | C49: 7 | D49: Hend | E49: 60 | F49: 12 | G49: 33 | H49: 15 | I49: 90 | J49: 18 | K49: 9 | L49: 49.5 | M49: 9 | N49: 13.5 | O49: 6.3 | P49: 11.7

Sheet Aya 
A1: Aya
E4: total leads
E5: =SUM(E20:E44) -> 1720
E9: won deals
E10: =SUM(F20:F44) -> 344
E14: total working days
E15: =COUNTIFS(D20:D44,A1) -> 25
B20: {=_xlfn._xlws.FILTER('9'!A:O,'9'!C:C='Aya '!A1,"not found")} -> 43465 | C20: 4 | D20: Aya | E20: 30 | F20: 6 | G20: 16.5 | H20: 7.5 | I20: 45 | J20: 9 | K20: 4.5 | L20: 24.75 | M20: 4.5 | N20: 6.75 | O20: 3.15 | P20: 5.85
B21: 43468 | C21: 4 | D21: Aya | E21: 20 | F21: 4 | G21: 11 | H21: 5 | I21: 30 | J21: 6 | K21: 3 | L21: 16.5 | M21: 3 | N21: 4.5 | O21: 2.1 | P21: 3.9
B22: 43469 | C22: 4 | D22: Aya | E22: 45 | F22: 9 | G22: 24.75 | H22: 11.25 | I22: 67.5 | J22: 13.5 | K22: 6.75 | L22: 37.125 | M22: 6.75 | N22: 10.125 | O22: 4.725 | P22: 8.775
B23: 43472 | C23: 4 | D23: Aya | E23: 50 | F23: 10 | G23: 27.5 | H23: 12.5 | I23: 75 | J23: 15 | K23: 7.5 | L23: 41.25 | M23: 7.5 | N23: 11.25 | O23: 5.25 | P23: 9.75
B24: 43479 | C24: 4 | D24: Aya | E24: 65 | F24: 13 | G24: 35.75 | H24: 16.25 | I24: 97.5 | J24: 19.5 | K24: 9.75 | L24: 53.625 | M24: 9.75 | N24: 14.625 | O24: 6.825 | P24: 12.675
B25: 43480 | C25: 4 | D25: Aya | E25: 63 | F25: 12.6 | G25: 34.65 | H25: 15.75 | I25: 94.5 | J25: 18.9 | K25: 9.45 | L25: 51.975 | M25: 9.45 | N25: 14.175 | O25: 6.615 | P25: 12.285
B26: 43482 | C26: 4 | D26: Aya | E26: 60 | F26: 12 | G26: 33 | H26: 15 | I26: 90 | J26: 18 | K26: 9 | L26: 49.5 | M26: 9 | N26: 13.5 | O26: 6.3 | P26: 11.7
B27: 43483 | C27: 4 | D27: Aya | E27: 50 | F27: 10 | G27: 27.5 | H27: 12.5 | I27: 75 | J27: 15 | K27: 7.5 | L27: 41.25 | M27: 7.5 | N27: 11.25 | O27: 5.25 | P27: 9.75
B28: 43484 | C28: 4 | D28: Aya | E28: 65 | F28: 13 | G28: 35.75 | H28: 16.25 | I28: 97.5 | J28: 19.5 | K28: 9.75 | L28: 53.625 | M28: 9.75 | N28: 14.625 | O28: 6.825 | P28: 12.675
B29: 43476 | C29: 4 | D29: Aya | E29: 33 | F29: 6.6 | G29: 18.15 | H29: 8.25 | I29: 49.5 | J29: 9.9 | K29: 4.95 | L29: 27.225 | M29: 4.95 | N29: 7.425 | O29: 3.465 | P29: 6.435
B30: 43486 | C30: 4 | D30: Aya | E30: 50 | F30: 10 | G30: 27.5 | H30: 12.5 | I30: 75 | J30: 15 | K30: 7.5 | L30: 41.25 | M30: 7.5 | N30: 11.25 | O30: 5.25 | P30: 9.75
B31: 43500 | C31: 4 | D31: Aya | E31: 60 | F31: 12 | G31: 33 | H31: 15 | I31: 90 | J31: 18 | K31: 9 | L31: 49.5 | M31: 9 | N31: 13.5 | O31: 6.3 | P31: 11.7
B32: 43502 | C32: 4 | D32: Aya | E32: 45 | F32: 9 | G32: 24.75 | H32: 11.25 | I32: 67.5 | J32: 13.5 | K32: 6.75 | L32: 37.125 | M32: 6.75 | N32: 10.125 | O32: 4.725 | P32: 8.775
... B44: 43514 | C44: 4 | D44: Aya | E44: 50 | F44: 10 | G44: 27.5 | H44: 12.5 | I44: 75 | J44: 15 | K44: 7.5 | L44: 41.25 | M44: 7.5 | N44: 11.25 | O44: 5.25 | P44: 9.75
